<?xml version="1.0"?>
<robot name="r2d2">
  <link name="base_link">
    <visual>
      <geometry>
        <box size="0.5 1.0 0.3" />
      </geometry>
    </visual>
  </link>

  <link name="front_suspension" >
    <visual>
      <origin xyz="0 0.4 0.0" rpy="0 1.57075 0" />
      <geometry>
        <cylinder length="0.7" radius="0.1" />
      </geometry>
    </visual>
  </link>

  <joint name="front_suspension_to_base_link" type="fixed">
    <parent link="base_link" />
    <child link="front_suspension" />
  </joint>


  <link name="back_suspension" >
    <visual>
      <origin xyz="0 -0.4 0.0" rpy="0 1.57075 0" />
      <geometry>
        <cylinder length="0.7" radius="0.1" />
      </geometry>
    </visual>
  </link>

  <joint name="back_suspension_to_base_link" type="fixed">
    <parent link="base_link" />
    <child link="back_suspension" />
  </joint>


  <link name="right_front_wheel" >
    <visual>
      <origin xyz="0.35 0.4 0" rpy="0 1.57075 0" />
      <geometry>
        <cylinder length="0.1" radius="0.2" />
      </geometry>
    </visual>
  </link>

  <joint name="joint_right_front_wheel" type="continuous">
    <parent link="base_link" />
    <child link="right_front_wheel" />
  </joint>


  <link name="left_front_wheel" >
    <visual>
      <origin xyz="-0.35 0.4 0" rpy="0 1.57075 0" />
      <geometry>
        <cylinder length="0.1" radius="0.2" />
      </geometry>
    </visual>
  </link>

  <joint name="joint_left_front_wheel" type="continuous">
    <parent link="base_link" />
    <child link="left_front_wheel" />
  </joint>
  

  <link name="right_back_wheel" >
    <visual>
      <origin xyz="0.35 -0.4 0" rpy="0 1.57075 0" />
      <geometry>
        <cylinder length="0.1" radius="0.2" />
      </geometry>
    </visual>
  </link>

  <joint name="joint_right_back_wheel" type="continuous">
    <parent link="base_link" />
    <child link="right_back_wheel" />
  </joint>


  <link name="left_back_wheel" >
    <visual>
      <origin xyz="-0.35 -0.4 0" rpy="0 1.57075 0" />
      <geometry>
        <cylinder length="0.1" radius="0.2" />
      </geometry>
    </visual>
  </link>

  <joint name="joint_left_back_wheel" type="continuous">
    <parent link="base_link" />
    <child link="left_back_wheel" />
  </joint>

</robot>
