<?xml version="1.0"?>
<robot name="r2d2" xmlns:xacro="http://www.ros.org/wiki/xacro"  >

  <material name="black">
    <color rgba="0.0 0.0 0.0 1.0" />
  </material>

  <material name="white">
    <color rgba="1.0 1.0 1.0 1.0" />
  </material>

  <material name="red">
    <color rgba="1.0 0.0 0.0 1.0" />
  </material>

  <material name="yellow">
    <color rgba="1.0 1.0 0.0 1.0" />
  </material>

  <!-- Not used yet -->
  <xacro:property name="body_xsize" value="0.5" />
  <xacro:property name="body_ysize" value="1.0" />
  <xacro:property name="body_zsize" value="0.3" />

  <xacro:property name="body_mass" value="2.0" />

  <link name="base_link" />

  <link name="chassis">
    <visual>
      <material name="black" />
      <geometry>
        <box size="0.5 1.0 0.3" />
      </geometry>
    </visual>
    <collision>
      <geometry>
        <box size="0.5 1.0 0.3" />
      </geometry>
    </collision>
    <inertial>
      <mass value="2.0" />
      <inertia ixx="${(1/12)*2*(1*1 + 0.3*0.3)}"     ixy="0.0"   ixz="0.0" iyy="${(1/12)*2*(0.5*0.5 + 0.3*0.3)}" iyz="0.0" izz="${(1/12)*2*(0.5*0.5 + 1*1)}" />
    </inertial>
  </link>

  <joint name="chassis_to_base_link" type="fixed">
    <parent link="base_link" />
    <child link="chassis" />
  </joint>

  <link name="front_suspension" >
    <visual>
      <material name="white"/>
      <origin xyz="0 0.4 0.0" rpy="0 1.57075 0" />
      <geometry>
        <cylinder length="0.7" radius="0.1" />
      </geometry>
    </visual>
    <collision>
      <origin xyz="0 0.4 0.0" rpy="0 1.57075 0" />
      <geometry>
        <cylinder length="0.7" radius="0.1" />
      </geometry>
    </collision>
  </link>

  <joint name="front_suspension_to_base_link" type="fixed">
    <parent link="chassis" />
    <child link="front_suspension" />
  </joint>

  <link name="front_right_steer_bar" >
    <visual>
      <material name="yellow"/>
      <origin rpy="0 1.57075 0" />
      <geometry>
        <cylinder length="0.1" radius="0.01" />
      </geometry>
    </visual>
    <inertial>
      <mass value="0.01"/>
      <origin xyz="0 0 0"/>
      <inertia ixx="0.01" ixy="0.0" ixz="0.0" iyy="0.01" iyz="0.0" izz="0.01"/>
    </inertial>
  </link>

  <joint name="joint_front_right_steer_bar" type="revolute">
    <parent link="chassis" />
    <child link="front_right_steer_bar" />
    <limit lower="-0.3" upper="0.3" effort="100" velocity="10" />
    <origin xyz="0.35 0.40 0.0" />
    <axis xyz="0 0 1" />
  </joint>

  <link name="front_left_steer_bar" >
    <visual>
      <material name="yellow"/>
      <origin rpy="0 1.57075 0" />
      <geometry>
        <cylinder length="0.1" radius="0.01" />
      </geometry>
    </visual>
    <inertial>
      <mass value="0.01"/>
      <origin xyz="0 0 0"/>
      <inertia ixx="0.01" ixy="0.0" ixz="0.0" iyy="0.01" iyz="0.0" izz="0.01"/>
    </inertial>
  </link>

  <joint name="joint_front_left_steer_bar" type="revolute">
    <parent link="chassis" />
    <child link="front_left_steer_bar" />
    <limit lower="-0.3" upper="0.3" effort="100" velocity="10" />
    <origin xyz="-0.35 0.40 0.0" />
    <axis xyz="0 0 1" />
  </joint>

  <link name="back_suspension" >
    <visual>
      <material name="white"/>
      <origin xyz="0 -0.4 0.0" rpy="0 1.57075 0" />
      <geometry>
        <cylinder length="0.7" radius="0.1" />
      </geometry>
    </visual>
    <collision>
      <origin xyz="0 -0.4 0.0" rpy="0 1.57075 0" />
      <geometry>
        <cylinder length="0.7" radius="0.1" />
      </geometry>
    </collision>
  </link>

  <joint name="back_suspension_to_base_link" type="fixed">
    <parent link="chassis" />
    <child link="back_suspension" />
  </joint>


  <link name="right_front_wheel" >
    <visual>
      <material name="red"/>
      <origin xyz="0.0 0.0 0.0" rpy="0 1.57075 0" />
      <geometry>
        <cylinder length="0.1" radius="0.2" />
      </geometry>
    </visual>
    <collision>
      <origin xyz="0.0 0.0 0.0" rpy="0 1.57075 0" />
      <geometry>
        <cylinder length="0.1" radius="0.2" />
      </geometry>
    </collision>
    <inertial>
      <mass value="0.2" />
      <inertia ixx="${(1/12)*0.2*(3*0.2*0.2 + 0.1*0.1)}"     ixy="0.0"   ixz="0.0" iyy="${(1/12)*0.2*(3*0.2*0.2 + 0.1*0.1)}" iyz="0.0" izz="${(1/12)*0.2*(0.2*0.2)}" />
    </inertial>
  </link>

  <joint name="joint_right_front_wheel" type="continuous">
    <parent link="front_right_steer_bar" />
    <child link="right_front_wheel" />
    <origin xyz="0.0 0.0 0.0" />
    <axis xyz="1 0 0"/>
  </joint>

  <link name="left_front_wheel" >
    <visual>
      <material name="red"/>
      <origin xyz="0.0 0.0 0.0" rpy="0 1.57075 0" />
      <geometry>
        <cylinder length="0.1" radius="0.2" />
      </geometry>
    </visual>
    <collision>
      <origin xyz="0.0 0.0 0.0" rpy="0 1.57075 0" />
      <geometry>
        <cylinder length="0.1" radius="0.2" />
      </geometry>
    </collision>
    <inertial>
      <mass value="0.2" />
      <inertia ixx="${(1/12)*0.2*(3*0.2*0.2 + 0.1*0.1)}"     ixy="0.0"   ixz="0.0" iyy="${(1/12)*0.2*(3*0.2*0.2 + 0.1*0.1)}" iyz="0.0" izz="${(1/12)*0.2*(0.2*0.2)}" />
    </inertial>
  </link>

  <joint name="joint_left_front_wheel" type="continuous">
    <parent link="front_left_steer_bar" />
    <child link="left_front_wheel" />
    <origin xyz="0.0 0.0 0.0" />
    <axis xyz="1 0 0"/>
  </joint>
  

  <link name="right_back_wheel" >
    <visual>
      <material name="red"/>
      <origin xyz="0 0 0" rpy="0 1.57075 0" />
      <geometry>
        <cylinder length="0.1" radius="0.2" />
      </geometry>
    </visual>
    <collision>
      <origin xyz="0 0 0" rpy="0 1.57075 0" />
      <geometry>
        <cylinder length="0.1" radius="0.2" />
      </geometry>
    </collision>
    <inertial>
      <mass value="0.2" />
      <inertia ixx="${(1/12)*0.2*(3*0.2*0.2 + 0.1*0.1)}"     ixy="0.0"   ixz="0.0" iyy="${(1/12)*0.2*(3*0.2*0.2 + 0.1*0.1)}" iyz="0.0" izz="${(1/12)*0.2*(0.2*0.2)}" />
    </inertial>
  </link>

  <joint name="joint_right_back_wheel" type="continuous">
    <parent link="base_link" />
    <child link="right_back_wheel" />
    <origin xyz="0.35 -0.4 0" />
    <axis xyz="1 0 0"/>
  </joint>


  <link name="left_back_wheel" >
    <visual>
      <material name="red"/>
      <origin xyz="0 0 0" rpy="0 1.57075 0" />
      <geometry>
        <cylinder length="0.1" radius="0.2" />
      </geometry>
    </visual>
    <collision>
      <origin xyz="0 0 0" rpy="0 1.57075 0" />
      <geometry>
        <cylinder length="0.1" radius="0.2" />
      </geometry>
    </collision>
    <inertial>
      <mass value="0.2" />
      <inertia ixx="${(1/12)*0.2*(3*0.2*0.2 + 0.1*0.1)}"     ixy="0.0"   ixz="0.0" iyy="${(1/12)*0.2*(3*0.2*0.2 + 0.1*0.1)}" iyz="0.0" izz="${(1/12)*0.2*(0.2*0.2)}" />
    </inertial>
  </link>

  <joint name="joint_left_back_wheel" type="continuous">
    <parent link="base_link" />
    <child link="left_back_wheel" />
    <origin xyz="-0.35 -0.4 0" />
    <axis xyz="1 0 0"/>
  </joint>

</robot>
